[2021-11-01 01:04:59,501] {taskinstance.py:1035} INFO - Dependencies all met for <TaskInstance: my_dag.permissions manual__2021-11-01T01:04:57.400568+00:00 [queued]>
[2021-11-01 01:04:59,515] {taskinstance.py:1035} INFO - Dependencies all met for <TaskInstance: my_dag.permissions manual__2021-11-01T01:04:57.400568+00:00 [queued]>
[2021-11-01 01:04:59,515] {taskinstance.py:1241} INFO - 
--------------------------------------------------------------------------------
[2021-11-01 01:04:59,515] {taskinstance.py:1242} INFO - Starting attempt 1 of 1
[2021-11-01 01:04:59,515] {taskinstance.py:1243} INFO - 
--------------------------------------------------------------------------------
[2021-11-01 01:04:59,526] {taskinstance.py:1262} INFO - Executing <Task(BashOperator): permissions> on 2021-11-01 01:04:57.400568+00:00
[2021-11-01 01:04:59,530] {standard_task_runner.py:52} INFO - Started process 1712 to run task
[2021-11-01 01:04:59,533] {standard_task_runner.py:76} INFO - Running: ['***', 'tasks', 'run', 'my_dag', 'permissions', 'manual__2021-11-01T01:04:57.400568+00:00', '--job-id', '39', '--raw', '--subdir', 'DAGS_FOLDER/checkModel.py', '--cfg-path', '/tmp/tmp90aqskwl', '--error-file', '/tmp/tmpihx4tb68']
[2021-11-01 01:04:59,533] {standard_task_runner.py:77} INFO - Job 39: Subtask permissions
[2021-11-01 01:04:59,571] {logging_mixin.py:109} INFO - Running <TaskInstance: my_dag.permissions manual__2021-11-01T01:04:57.400568+00:00 [running]> on host 7b304be9cff3
[2021-11-01 01:04:59,617] {taskinstance.py:1429} INFO - Exporting the following env vars:
AIRFLOW_CTX_DAG_OWNER=***
AIRFLOW_CTX_DAG_ID=my_dag
AIRFLOW_CTX_TASK_ID=permissions
AIRFLOW_CTX_EXECUTION_DATE=2021-11-01T01:04:57.400568+00:00
AIRFLOW_CTX_DAG_RUN_ID=manual__2021-11-01T01:04:57.400568+00:00
[2021-11-01 01:04:59,618] {subprocess.py:62} INFO - Tmp dir root location: 
 /tmp
[2021-11-01 01:04:59,618] {subprocess.py:74} INFO - Running command: ['bash', '-c', 'chmod 777 /opt/***mydata/test.csv']
[2021-11-01 01:04:59,628] {subprocess.py:85} INFO - Output:
[2021-11-01 01:04:59,631] {subprocess.py:89} INFO - chmod: cannot access '/opt/***mydata/test.csv': No such file or directory
[2021-11-01 01:04:59,631] {subprocess.py:93} INFO - Command exited with return code 1
[2021-11-01 01:04:59,643] {taskinstance.py:1703} ERROR - Task failed with exception
Traceback (most recent call last):
  File "/home/airflow/.local/lib/python3.7/site-packages/airflow/models/taskinstance.py", line 1332, in _run_raw_task
    self._execute_task_with_callbacks(context)
  File "/home/airflow/.local/lib/python3.7/site-packages/airflow/models/taskinstance.py", line 1458, in _execute_task_with_callbacks
    result = self._execute_task(context, self.task)
  File "/home/airflow/.local/lib/python3.7/site-packages/airflow/models/taskinstance.py", line 1514, in _execute_task
    result = execute_callable(context=context)
  File "/home/airflow/.local/lib/python3.7/site-packages/airflow/operators/bash.py", line 188, in execute
    f'Bash command failed. The command returned a non-zero exit code {result.exit_code}.'
airflow.exceptions.AirflowException: Bash command failed. The command returned a non-zero exit code 1.
[2021-11-01 01:04:59,649] {taskinstance.py:1280} INFO - Marking task as FAILED. dag_id=my_dag, task_id=permissions, execution_date=20211101T010457, start_date=20211101T010459, end_date=20211101T010459
[2021-11-01 01:04:59,660] {standard_task_runner.py:91} ERROR - Failed to execute job 39 for task permissions
Traceback (most recent call last):
  File "/home/airflow/.local/lib/python3.7/site-packages/airflow/task/task_runner/standard_task_runner.py", line 85, in _start_by_fork
    args.func(args, dag=self.dag)
  File "/home/airflow/.local/lib/python3.7/site-packages/airflow/cli/cli_parser.py", line 48, in command
    return func(*args, **kwargs)
  File "/home/airflow/.local/lib/python3.7/site-packages/airflow/utils/cli.py", line 92, in wrapper
    return f(*args, **kwargs)
  File "/home/airflow/.local/lib/python3.7/site-packages/airflow/cli/commands/task_command.py", line 292, in task_run
    _run_task_by_selected_method(args, dag, ti)
  File "/home/airflow/.local/lib/python3.7/site-packages/airflow/cli/commands/task_command.py", line 107, in _run_task_by_selected_method
    _run_raw_task(args, ti)
  File "/home/airflow/.local/lib/python3.7/site-packages/airflow/cli/commands/task_command.py", line 184, in _run_raw_task
    error_file=args.error_file,
  File "/home/airflow/.local/lib/python3.7/site-packages/airflow/utils/session.py", line 70, in wrapper
    return func(*args, session=session, **kwargs)
  File "/home/airflow/.local/lib/python3.7/site-packages/airflow/models/taskinstance.py", line 1332, in _run_raw_task
    self._execute_task_with_callbacks(context)
  File "/home/airflow/.local/lib/python3.7/site-packages/airflow/models/taskinstance.py", line 1458, in _execute_task_with_callbacks
    result = self._execute_task(context, self.task)
  File "/home/airflow/.local/lib/python3.7/site-packages/airflow/models/taskinstance.py", line 1514, in _execute_task
    result = execute_callable(context=context)
  File "/home/airflow/.local/lib/python3.7/site-packages/airflow/operators/bash.py", line 188, in execute
    f'Bash command failed. The command returned a non-zero exit code {result.exit_code}.'
airflow.exceptions.AirflowException: Bash command failed. The command returned a non-zero exit code 1.
[2021-11-01 01:04:59,704] {local_task_job.py:154} INFO - Task exited with return code 1
[2021-11-01 01:04:59,751] {local_task_job.py:264} INFO - 0 downstream tasks scheduled from follow-on schedule check
