[2021-10-30 20:22:31,206] {taskinstance.py:1035} INFO - Dependencies all met for <TaskInstance: my_dag.create_passenger_table manual__2021-10-30T20:22:28.914336+00:00 [queued]>
[2021-10-30 20:22:31,255] {taskinstance.py:1035} INFO - Dependencies all met for <TaskInstance: my_dag.create_passenger_table manual__2021-10-30T20:22:28.914336+00:00 [queued]>
[2021-10-30 20:22:31,255] {taskinstance.py:1241} INFO - 
--------------------------------------------------------------------------------
[2021-10-30 20:22:31,256] {taskinstance.py:1242} INFO - Starting attempt 1 of 1
[2021-10-30 20:22:31,256] {taskinstance.py:1243} INFO - 
--------------------------------------------------------------------------------
[2021-10-30 20:22:31,279] {taskinstance.py:1262} INFO - Executing <Task(PostgresOperator): create_passenger_table> on 2021-10-30 20:22:28.914336+00:00
[2021-10-30 20:22:31,290] {standard_task_runner.py:76} INFO - Running: ['***', 'tasks', 'run', 'my_dag', 'create_passenger_table', 'manual__2021-10-30T20:22:28.914336+00:00', '--job-id', '41', '--raw', '--subdir', 'DAGS_FOLDER/checkingmodel.py', '--cfg-path', '/tmp/tmpza2fh46g', '--error-file', '/tmp/tmp95_gi0y9']
[2021-10-30 20:22:31,291] {standard_task_runner.py:77} INFO - Job 41: Subtask create_passenger_table
[2021-10-30 20:22:31,285] {standard_task_runner.py:52} INFO - Started process 5412 to run task
[2021-10-30 20:22:31,358] {logging_mixin.py:109} INFO - Running <TaskInstance: my_dag.create_passenger_table manual__2021-10-30T20:22:28.914336+00:00 [running]> on host 54578bcb1e9c
[2021-10-30 20:22:31,442] {taskinstance.py:1414} INFO - Exporting the following env vars:
AIRFLOW_CTX_DAG_OWNER=***
AIRFLOW_CTX_DAG_ID=my_dag
AIRFLOW_CTX_TASK_ID=create_passenger_table
AIRFLOW_CTX_EXECUTION_DATE=2021-10-30T20:22:28.914336+00:00
AIRFLOW_CTX_DAG_RUN_ID=manual__2021-10-30T20:22:28.914336+00:00
[2021-10-30 20:22:31,458] {taskinstance.py:1686} ERROR - Task failed with exception
Traceback (most recent call last):
  File "/home/airflow/.local/lib/python3.6/site-packages/airflow/models/taskinstance.py", line 1324, in _run_raw_task
    self._execute_task_with_callbacks(context)
  File "/home/airflow/.local/lib/python3.6/site-packages/airflow/models/taskinstance.py", line 1443, in _execute_task_with_callbacks
    result = self._execute_task(context, self.task)
  File "/home/airflow/.local/lib/python3.6/site-packages/airflow/models/taskinstance.py", line 1499, in _execute_task
    result = execute_callable(context=context)
  File "/home/airflow/.local/lib/python3.6/site-packages/airflow/providers/postgres/operators/postgres.py", line 69, in execute
    self.hook.run(self.sql, self.autocommit, parameters=self.parameters)
  File "/home/airflow/.local/lib/python3.6/site-packages/airflow/hooks/dbapi.py", line 198, in run
    with closing(self.get_conn()) as conn:
  File "/home/airflow/.local/lib/python3.6/site-packages/airflow/providers/postgres/hooks/postgres.py", line 115, in get_conn
    self.conn = psycopg2.connect(**conn_args)
  File "/home/airflow/.local/lib/python3.6/site-packages/psycopg2/__init__.py", line 122, in connect
    conn = _connect(dsn, connection_factory=connection_factory, **kwasync)
psycopg2.OperationalError: could not connect to server: No such file or directory
	Is the server running locally and accepting
	connections on Unix domain socket "/var/run/postgresql/.s.PGSQL.5432"?

[2021-10-30 20:22:31,483] {taskinstance.py:1280} INFO - Marking task as FAILED. dag_id=my_dag, task_id=create_passenger_table, execution_date=20211030T202228, start_date=20211030T202231, end_date=20211030T202231
[2021-10-30 20:22:31,506] {standard_task_runner.py:91} ERROR - Failed to execute job 41 for task create_passenger_table
Traceback (most recent call last):
  File "/home/airflow/.local/lib/python3.6/site-packages/airflow/task/task_runner/standard_task_runner.py", line 85, in _start_by_fork
    args.func(args, dag=self.dag)
  File "/home/airflow/.local/lib/python3.6/site-packages/airflow/cli/cli_parser.py", line 48, in command
    return func(*args, **kwargs)
  File "/home/airflow/.local/lib/python3.6/site-packages/airflow/utils/cli.py", line 92, in wrapper
    return f(*args, **kwargs)
  File "/home/airflow/.local/lib/python3.6/site-packages/airflow/cli/commands/task_command.py", line 292, in task_run
    _run_task_by_selected_method(args, dag, ti)
  File "/home/airflow/.local/lib/python3.6/site-packages/airflow/cli/commands/task_command.py", line 107, in _run_task_by_selected_method
    _run_raw_task(args, ti)
  File "/home/airflow/.local/lib/python3.6/site-packages/airflow/cli/commands/task_command.py", line 184, in _run_raw_task
    error_file=args.error_file,
  File "/home/airflow/.local/lib/python3.6/site-packages/airflow/utils/session.py", line 70, in wrapper
    return func(*args, session=session, **kwargs)
  File "/home/airflow/.local/lib/python3.6/site-packages/airflow/models/taskinstance.py", line 1324, in _run_raw_task
    self._execute_task_with_callbacks(context)
  File "/home/airflow/.local/lib/python3.6/site-packages/airflow/models/taskinstance.py", line 1443, in _execute_task_with_callbacks
    result = self._execute_task(context, self.task)
  File "/home/airflow/.local/lib/python3.6/site-packages/airflow/models/taskinstance.py", line 1499, in _execute_task
    result = execute_callable(context=context)
  File "/home/airflow/.local/lib/python3.6/site-packages/airflow/providers/postgres/operators/postgres.py", line 69, in execute
    self.hook.run(self.sql, self.autocommit, parameters=self.parameters)
  File "/home/airflow/.local/lib/python3.6/site-packages/airflow/hooks/dbapi.py", line 198, in run
    with closing(self.get_conn()) as conn:
  File "/home/airflow/.local/lib/python3.6/site-packages/airflow/providers/postgres/hooks/postgres.py", line 115, in get_conn
    self.conn = psycopg2.connect(**conn_args)
  File "/home/airflow/.local/lib/python3.6/site-packages/psycopg2/__init__.py", line 122, in connect
    conn = _connect(dsn, connection_factory=connection_factory, **kwasync)
psycopg2.OperationalError: could not connect to server: No such file or directory
	Is the server running locally and accepting
	connections on Unix domain socket "/var/run/postgresql/.s.PGSQL.5432"?

[2021-10-30 20:22:31,547] {local_task_job.py:154} INFO - Task exited with return code 1
[2021-10-30 20:22:31,637] {local_task_job.py:264} INFO - 0 downstream tasks scheduled from follow-on schedule check
