[2021-10-29 22:59:36,732] {taskinstance.py:1035} INFO - Dependencies all met for <TaskInstance: my_dag.create_passenger_table manual__2021-10-29T22:59:35.557686+00:00 [queued]>
[2021-10-29 22:59:36,743] {taskinstance.py:1035} INFO - Dependencies all met for <TaskInstance: my_dag.create_passenger_table manual__2021-10-29T22:59:35.557686+00:00 [queued]>
[2021-10-29 22:59:36,743] {taskinstance.py:1241} INFO - 
--------------------------------------------------------------------------------
[2021-10-29 22:59:36,744] {taskinstance.py:1242} INFO - Starting attempt 1 of 1
[2021-10-29 22:59:36,744] {taskinstance.py:1243} INFO - 
--------------------------------------------------------------------------------
[2021-10-29 22:59:36,753] {taskinstance.py:1262} INFO - Executing <Task(PostgresOperator): create_passenger_table> on 2021-10-29 22:59:35.557686+00:00
[2021-10-29 22:59:36,758] {standard_task_runner.py:76} INFO - Running: ['***', 'tasks', 'run', 'my_dag', 'create_passenger_table', 'manual__2021-10-29T22:59:35.557686+00:00', '--job-id', '38', '--raw', '--subdir', 'DAGS_FOLDER/checkingmodel.py', '--cfg-path', '/tmp/tmp6tsic_ae', '--error-file', '/tmp/tmpuiqip8cy']
[2021-10-29 22:59:36,759] {standard_task_runner.py:77} INFO - Job 38: Subtask create_passenger_table
[2021-10-29 22:59:36,756] {standard_task_runner.py:52} INFO - Started process 295 to run task
[2021-10-29 22:59:36,784] {logging_mixin.py:109} INFO - Running <TaskInstance: my_dag.create_passenger_table manual__2021-10-29T22:59:35.557686+00:00 [running]> on host 54578bcb1e9c
[2021-10-29 22:59:36,819] {taskinstance.py:1414} INFO - Exporting the following env vars:
AIRFLOW_CTX_DAG_OWNER=***
AIRFLOW_CTX_DAG_ID=my_dag
AIRFLOW_CTX_TASK_ID=create_passenger_table
AIRFLOW_CTX_EXECUTION_DATE=2021-10-29T22:59:35.557686+00:00
AIRFLOW_CTX_DAG_RUN_ID=manual__2021-10-29T22:59:35.557686+00:00
[2021-10-29 22:59:36,825] {taskinstance.py:1686} ERROR - Task failed with exception
Traceback (most recent call last):
  File "/home/airflow/.local/lib/python3.6/site-packages/airflow/models/taskinstance.py", line 1324, in _run_raw_task
    self._execute_task_with_callbacks(context)
  File "/home/airflow/.local/lib/python3.6/site-packages/airflow/models/taskinstance.py", line 1443, in _execute_task_with_callbacks
    result = self._execute_task(context, self.task)
  File "/home/airflow/.local/lib/python3.6/site-packages/airflow/models/taskinstance.py", line 1499, in _execute_task
    result = execute_callable(context=context)
  File "/home/airflow/.local/lib/python3.6/site-packages/airflow/providers/postgres/operators/postgres.py", line 69, in execute
    self.hook.run(self.sql, self.autocommit, parameters=self.parameters)
  File "/home/airflow/.local/lib/python3.6/site-packages/airflow/hooks/dbapi.py", line 198, in run
    with closing(self.get_conn()) as conn:
  File "/home/airflow/.local/lib/python3.6/site-packages/airflow/providers/postgres/hooks/postgres.py", line 88, in get_conn
    conn = deepcopy(self.connection or self.get_connection(conn_id))
  File "/home/airflow/.local/lib/python3.6/site-packages/airflow/hooks/base.py", line 68, in get_connection
    conn = Connection.get_connection_from_secrets(conn_id)
  File "/home/airflow/.local/lib/python3.6/site-packages/airflow/models/connection.py", line 410, in get_connection_from_secrets
    raise AirflowNotFoundException(f"The conn_id `{conn_id}` isn't defined")
airflow.exceptions.AirflowNotFoundException: The conn_id `postgres_default` isn't defined
[2021-10-29 22:59:36,835] {taskinstance.py:1280} INFO - Marking task as FAILED. dag_id=my_dag, task_id=create_passenger_table, execution_date=20211029T225935, start_date=20211029T225936, end_date=20211029T225936
[2021-10-29 22:59:36,844] {standard_task_runner.py:91} ERROR - Failed to execute job 38 for task create_passenger_table
Traceback (most recent call last):
  File "/home/airflow/.local/lib/python3.6/site-packages/airflow/task/task_runner/standard_task_runner.py", line 85, in _start_by_fork
    args.func(args, dag=self.dag)
  File "/home/airflow/.local/lib/python3.6/site-packages/airflow/cli/cli_parser.py", line 48, in command
    return func(*args, **kwargs)
  File "/home/airflow/.local/lib/python3.6/site-packages/airflow/utils/cli.py", line 92, in wrapper
    return f(*args, **kwargs)
  File "/home/airflow/.local/lib/python3.6/site-packages/airflow/cli/commands/task_command.py", line 292, in task_run
    _run_task_by_selected_method(args, dag, ti)
  File "/home/airflow/.local/lib/python3.6/site-packages/airflow/cli/commands/task_command.py", line 107, in _run_task_by_selected_method
    _run_raw_task(args, ti)
  File "/home/airflow/.local/lib/python3.6/site-packages/airflow/cli/commands/task_command.py", line 184, in _run_raw_task
    error_file=args.error_file,
  File "/home/airflow/.local/lib/python3.6/site-packages/airflow/utils/session.py", line 70, in wrapper
    return func(*args, session=session, **kwargs)
  File "/home/airflow/.local/lib/python3.6/site-packages/airflow/models/taskinstance.py", line 1324, in _run_raw_task
    self._execute_task_with_callbacks(context)
  File "/home/airflow/.local/lib/python3.6/site-packages/airflow/models/taskinstance.py", line 1443, in _execute_task_with_callbacks
    result = self._execute_task(context, self.task)
  File "/home/airflow/.local/lib/python3.6/site-packages/airflow/models/taskinstance.py", line 1499, in _execute_task
    result = execute_callable(context=context)
  File "/home/airflow/.local/lib/python3.6/site-packages/airflow/providers/postgres/operators/postgres.py", line 69, in execute
    self.hook.run(self.sql, self.autocommit, parameters=self.parameters)
  File "/home/airflow/.local/lib/python3.6/site-packages/airflow/hooks/dbapi.py", line 198, in run
    with closing(self.get_conn()) as conn:
  File "/home/airflow/.local/lib/python3.6/site-packages/airflow/providers/postgres/hooks/postgres.py", line 88, in get_conn
    conn = deepcopy(self.connection or self.get_connection(conn_id))
  File "/home/airflow/.local/lib/python3.6/site-packages/airflow/hooks/base.py", line 68, in get_connection
    conn = Connection.get_connection_from_secrets(conn_id)
  File "/home/airflow/.local/lib/python3.6/site-packages/airflow/models/connection.py", line 410, in get_connection_from_secrets
    raise AirflowNotFoundException(f"The conn_id `{conn_id}` isn't defined")
airflow.exceptions.AirflowNotFoundException: The conn_id `postgres_default` isn't defined
[2021-10-29 22:59:36,852] {local_task_job.py:154} INFO - Task exited with return code 1
[2021-10-29 22:59:36,929] {local_task_job.py:264} INFO - 0 downstream tasks scheduled from follow-on schedule check
