[2021-11-01 03:19:53,820] {taskinstance.py:1035} INFO - Dependencies all met for <TaskInstance: my_dag.processdata manual__2021-11-01T03:19:49.507915+00:00 [queued]>
[2021-11-01 03:19:53,829] {taskinstance.py:1035} INFO - Dependencies all met for <TaskInstance: my_dag.processdata manual__2021-11-01T03:19:49.507915+00:00 [queued]>
[2021-11-01 03:19:53,829] {taskinstance.py:1241} INFO - 
--------------------------------------------------------------------------------
[2021-11-01 03:19:53,829] {taskinstance.py:1242} INFO - Starting attempt 1 of 1
[2021-11-01 03:19:53,829] {taskinstance.py:1243} INFO - 
--------------------------------------------------------------------------------
[2021-11-01 03:19:53,841] {taskinstance.py:1262} INFO - Executing <Task(PythonOperator): processdata> on 2021-11-01 03:19:49.507915+00:00
[2021-11-01 03:19:53,845] {standard_task_runner.py:52} INFO - Started process 4943 to run task
[2021-11-01 03:19:53,847] {standard_task_runner.py:76} INFO - Running: ['***', 'tasks', 'run', 'my_dag', 'processdata', 'manual__2021-11-01T03:19:49.507915+00:00', '--job-id', '111', '--raw', '--subdir', 'DAGS_FOLDER/checkModel.py', '--cfg-path', '/tmp/tmp16vv3bws', '--error-file', '/tmp/tmpa3wuvbrc']
[2021-11-01 03:19:53,848] {standard_task_runner.py:77} INFO - Job 111: Subtask processdata
[2021-11-01 03:19:53,876] {logging_mixin.py:109} INFO - Running <TaskInstance: my_dag.processdata manual__2021-11-01T03:19:49.507915+00:00 [running]> on host 93c37aa78767
[2021-11-01 03:19:53,910] {taskinstance.py:1429} INFO - Exporting the following env vars:
AIRFLOW_CTX_DAG_OWNER=***
AIRFLOW_CTX_DAG_ID=my_dag
AIRFLOW_CTX_TASK_ID=processdata
AIRFLOW_CTX_EXECUTION_DATE=2021-11-01T03:19:49.507915+00:00
AIRFLOW_CTX_DAG_RUN_ID=manual__2021-11-01T03:19:49.507915+00:00
[2021-11-01 03:19:53,911] {taskinstance.py:1703} ERROR - Task failed with exception
Traceback (most recent call last):
  File "/home/airflow/.local/lib/python3.7/site-packages/airflow/models/taskinstance.py", line 1332, in _run_raw_task
    self._execute_task_with_callbacks(context)
  File "/home/airflow/.local/lib/python3.7/site-packages/airflow/models/taskinstance.py", line 1458, in _execute_task_with_callbacks
    result = self._execute_task(context, self.task)
  File "/home/airflow/.local/lib/python3.7/site-packages/airflow/models/taskinstance.py", line 1514, in _execute_task
    result = execute_callable(context=context)
  File "/home/airflow/.local/lib/python3.7/site-packages/airflow/operators/python.py", line 151, in execute
    return_value = self.execute_callable()
  File "/home/airflow/.local/lib/python3.7/site-packages/airflow/operators/python.py", line 162, in execute_callable
    return self.python_callable(*self.op_args, **self.op_kwargs)
  File "/opt/airflow/dags/checkModel.py", line 31, in process_data
    model = pickle.load(open("{ah}/mydata/logistic_regression.pickle".format(ah=ah), "rb"))
ModuleNotFoundError: No module named 'sklearn'
[2021-11-01 03:19:53,920] {taskinstance.py:1280} INFO - Marking task as FAILED. dag_id=my_dag, task_id=processdata, execution_date=20211101T031949, start_date=20211101T031953, end_date=20211101T031953
[2021-11-01 03:19:53,930] {standard_task_runner.py:91} ERROR - Failed to execute job 111 for task processdata
Traceback (most recent call last):
  File "/home/airflow/.local/lib/python3.7/site-packages/airflow/task/task_runner/standard_task_runner.py", line 85, in _start_by_fork
    args.func(args, dag=self.dag)
  File "/home/airflow/.local/lib/python3.7/site-packages/airflow/cli/cli_parser.py", line 48, in command
    return func(*args, **kwargs)
  File "/home/airflow/.local/lib/python3.7/site-packages/airflow/utils/cli.py", line 92, in wrapper
    return f(*args, **kwargs)
  File "/home/airflow/.local/lib/python3.7/site-packages/airflow/cli/commands/task_command.py", line 292, in task_run
    _run_task_by_selected_method(args, dag, ti)
  File "/home/airflow/.local/lib/python3.7/site-packages/airflow/cli/commands/task_command.py", line 107, in _run_task_by_selected_method
    _run_raw_task(args, ti)
  File "/home/airflow/.local/lib/python3.7/site-packages/airflow/cli/commands/task_command.py", line 184, in _run_raw_task
    error_file=args.error_file,
  File "/home/airflow/.local/lib/python3.7/site-packages/airflow/utils/session.py", line 70, in wrapper
    return func(*args, session=session, **kwargs)
  File "/home/airflow/.local/lib/python3.7/site-packages/airflow/models/taskinstance.py", line 1332, in _run_raw_task
    self._execute_task_with_callbacks(context)
  File "/home/airflow/.local/lib/python3.7/site-packages/airflow/models/taskinstance.py", line 1458, in _execute_task_with_callbacks
    result = self._execute_task(context, self.task)
  File "/home/airflow/.local/lib/python3.7/site-packages/airflow/models/taskinstance.py", line 1514, in _execute_task
    result = execute_callable(context=context)
  File "/home/airflow/.local/lib/python3.7/site-packages/airflow/operators/python.py", line 151, in execute
    return_value = self.execute_callable()
  File "/home/airflow/.local/lib/python3.7/site-packages/airflow/operators/python.py", line 162, in execute_callable
    return self.python_callable(*self.op_args, **self.op_kwargs)
  File "/opt/airflow/dags/checkModel.py", line 31, in process_data
    model = pickle.load(open("{ah}/mydata/logistic_regression.pickle".format(ah=ah), "rb"))
ModuleNotFoundError: No module named 'sklearn'
[2021-11-01 03:19:53,939] {local_task_job.py:154} INFO - Task exited with return code 1
[2021-11-01 03:19:53,963] {local_task_job.py:264} INFO - 0 downstream tasks scheduled from follow-on schedule check
